Workbook

Sheet out_language_pt
A1: 0
A2: 语言总表
A3: 索引ID | B3: 内容 | C3: 中文，用于导出（不要在原表简转繁）
A4: 1*1 | B4: stack_error,n_list
A5: id | B5: text
A6: int | B6: string
A7: id | B7: text
A8: int | B8: ori_string
A9: 100001 | B9: Modelo de e-mail em texto para a plataforma T | C9: T后台纯文本邮件模板 | D9: =VLOOKUP(A9,Sheet1!A:B,2,0) | E9: D列为简中语言表的文本，若CD列中文本冲突，以D列为准
A10: 100002 | B10: Texto da plataforma T + modelo de e-mail de recompensa | C10: T后台文本+奖励邮件模板 | D10: =VLOOKUP(A10,Sheet1!A:B,2,0)
A11: 100003 | B11: Guerreiro Cogumelo | C11: 菇勇者 | D11: =VLOOKUP(A11,Sheet1!A:B,2,0)
A12: 100004 | B12: Guerreiro | C12: 战士 | D12: =VLOOKUP(A12,Sheet1!A:B,2,0)
A13: 100005 | B13: Arqueiro | C13: 弓箭手 | D13: =VLOOKUP(A13,Sheet1!A:B,2,0)
A14: 100006 | B14: Mago | C14: 法师 | D14: =VLOOKUP(A14,Sheet1!A:B,2,0)
A15: 100007 | B15: Espadachim | C15: 剑客 | D15: =VLOOKUP(A15,Sheet1!A:B,2,0)
A16: 100008 | B16: Escoteiro | C16: 斧武士 | D16: =VLOOKUP(A16,Sheet1!A:B,2,0)
A17: 100009 | B17: Caçador das Sombras | C17: 狙影猎手 | D17: =VLOOKUP(A17,Sheet1!A:B,2,0)
A18: 100010 | B18: Arqueiro do Vento | C18: 风弩手 | D18: =VLOOKUP(A18,Sheet1!A:B,2,0)
A19: 100011 | B19: Curandeiro | C19: 愈灵师 | D19: =VLOOKUP(A19,Sheet1!A:B,2,0)
A20: 100012 | B20: Espiritista | C20: 魔灵士 | D20: =VLOOKUP(A20,Sheet1!A:B,2,0)
A21: 100013 | B21: Paladino | C21: 大剑士 | D21: =VLOOKUP(A21,Sheet1!A:B,2,0)
... A4418: 200094 | B4418: Consumir %s? | C4418: 是否消耗%s | D4418: =VLOOKUP(A4418,Sheet1!A:B,2,0)
A4419: 700024509 | B4419: Consumir ##1*##2? | C4419: 是否消耗##1*##2
A4420: 200095 | B4420: Reforjar | C4420: 重铸 | D4420: =VLOOKUP(A4420,Sheet1!A:B,2,0)
A4421: 200096 | B4421: <b><color=#544231>Meta de Milhagem: alcançar Milhagem</color> <color=#ab630e>%s</color></b> | C4421: <b><color=#544231>里程目标：里程值达到</color><color=#ab630e>%s</color></b> | D4421: =VLOOKUP(A4421,Sheet1!A:B,2,0)
A4422: 200097 | B4422: <b><color=#544231>Meta de Milhagem: concluir a instância do evento</color> <color=#ab630e>%s</color></b> | C4422: <b><color=#544231>里程目标：通关活动副本</color><color=#ab630e>%s</color></b> | D4422: =VLOOKUP(A4422,Sheet1!A:B,2,0)
A4423: 200098 | B4423: Efeitos em batalha: %s | C4423: 上阵效果：%s | D4423: =VLOOKUP(A4423,Sheet1!A:B,2,0)
A4424: 200099 | B4424: Vida básica, ATQ e Defesa +%s% | C4424: 基础生命&攻击&防御+%s% | D4424: =VLOOKUP(A4424,Sheet1!A:B,2,0)
A4425: 200100 | B4425: Sem companheiro para equipar | C4425: 没有可以装配的同伴 | D4425: =VLOOKUP(A4425,Sheet1!A:B,2,0)
A4426: 200101 | B4426: Desbloquear | C4426: 解锁 | D4426: =VLOOKUP(A4426,Sheet1!A:B,2,0)
A4427: 200102 | B4427: Horário do evento: %s | C4427: 活动时间：%s | D4427: =VLOOKUP(A4427,Sheet1!A:B,2,0)
A4428: 200103 | B4428: Atributos básicos | C4428: 基础属性 | D4428: =VLOOKUP(A4428,Sheet1!A:B,2,0)
A4429: 200104 | B4429: Atributos avançados | C4429: 高级属性 | D4429: =VLOOKUP(A4429,Sheet1!A:B,2,0)
A4430: 200105 | B4430: Atributos finais | C4430: 最终属性 | D4430: =VLOOKUP(A4430,Sheet1!A:B,2,0)
A4431: 200106 | B4431: Nível insuficiente | C4431: 等级不足 | D4431: =VLOOKUP(A4431,Sheet1!A:B,2,0)
... A5004: 200685 | B5004: Dano: %s | C5004: 伤害：%s | D5004: =VLOOKUP(A5004,Sheet1!A:B,2,0)
A5005: 200686 | B5005: 1 | C5005: 一个 | D5005: =VLOOKUP(A5005,Sheet1!A:B,2,0)
A5006: 200687 | B5006: 2 | C5006: 两个 | D5006: =VLOOKUP(A5006,Sheet1!A:B,2,0)
A5007: 200688 | B5007: 3 | C5007: 三个 | D5007: =VLOOKUP(A5007,Sheet1!A:B,2,0)
A5008: 200689 | B5008: 4 | C5008: 四个 | D5008: =VLOOKUP(A5008,Sheet1!A:B,2,0)
...

Sheet Sheet1
A1: 0
A2: 语言总表
A3: 索引ID | B3: 内容
A4: 1*1 | B4: stack_error,n_list | D4: 外语查找用这列
A5: id | B5: text
A6: int | B6: string
A7: id | B7: text
A8: int | B8: ori_string
A9: 100001 | B9: T后台纯文本邮件模板 | D9: T后台纯文本邮件模板
A10: 100002 | B10: T后台文本+奖励邮件模板 | D10: T后台文本+奖励邮件模板
A11: 100003 | B11: 菇勇者 | D11: 菇勇者
A12: 100004 | B12: 战士 | D12: 战士
A13: 100005 | B13: 弓箭手 | D13: 弓箭手
A14: 100006 | B14: 法师 | D14: 法师
A15: 100007 | B15: 剑客 | D15: 剑客
A16: 100008 | B16: 斧武士 | D16: 斧武士
A17: 100009 | B17: 狙影猎手 | D17: 狙影猎手
A18: 100010 | B18: 风弩手 | D18: 风弩手
A19: 100011 | B19: 愈灵师 | D19: 愈灵师
A20: 100012 | B20: 魔灵士 | D20: 魔灵士
... A13293: 700000003 | B13293: 增加##1%暴击,笨尼攻击有##2%概率击飞目标##3秒 | D13293: 当前难度开放满3天且通关时防御值为10解锁扫荡
A13294: 700000002 | D13294: 通关当前难度且防御值为10时解锁扫荡
A13295: 400080 | B13295: 待寻找 | D13295: 悲伤蛙好感：
A13296: 400534 | B13296: 当前难度开放满3天且通关时防御值为10解锁扫荡 | D13296: 悲伤蛙宇宙
A13297: 400535 | B13297: 通关当前难度且防御值为10时解锁扫荡 | D13297: 躲蛙蛙
A13298: 400536 | B13298: 悲伤蛙好感： | D13298: 守卫佛系蛙
A13299: 400537 | B13299: 悲伤蛙宇宙 | D13299: 失眠蛙
A13300: 400538 | B13300: 躲蛙蛙 | D13300: 星球之旅
A13301: 400539 | B13301: 守卫佛系蛙 | D13301: 高光时刻
A13302: 400540 | B13302: 失眠蛙 | D13302: 打爆不开心
A13303: 400541 | B13303: 星球之旅 | D13303: 太空历险蛙
A13304: 400542 | B13304: 高光时刻 | D13304: 以剩余守卫点≥5通关关卡1
A13305: 400543 | B13305: 打爆不开心 | D13305: 以剩余守卫点≥3通关关卡1
A13306: 400544 | B13306: 太空历险蛙 | D13306: 以剩余守卫点≥1通关关卡1
... A14257: 600000339 | B14257: 解锁高级背饰\n“天外来物” | D14257: 0点-8点为休战期，无法发起抢占
A14258: 600000340 | B14258: 用于解锁背饰天外来物的道具
A14259: 600000341 | B14259: 万仞穿刺
A14260: 600000342 | B14260: 流血（普攻伤害）
A14261: 600000343 | B14261: 使敌人受到伤害增加陷阱
A14262: 600000344 | B14262: 使敌人受到伤害增加
...
