Workbook

Sheet out_language_ar
A1: 0
A2: 语言总表
A3: 索引ID | B3: 内容
A4: 1*1 | B4: stack_error,n_list
A5: id | B5: text
A6: int | B6: string
A7: id | B7: text
A8: int | B8: ori_string
A9: 100001 | B9: قالب بريد بنص عادي بخلفية T | C9: T后台纯文本邮件模板 | E9: D列为简中语言表的文本，若CD列中文本冲突，以D列为准
A10: 100002 | B10: قالب بريد المكافآت + نص خلفية T | C10: T后台文本+奖励邮件模板
A11: 100003 | B11: المشروم الشجاع | C11: 菇勇者
A12: 100004 | B12: محارب | C12: 战士
A13: 100005 | B13: رامي السهام | C13: 弓箭手
A14: 100006 | B14: ساحر | C14: 法师
A15: 100007 | B15: مبارز | C15: 剑客
A16: 100008 | B16: محارب الفأس | C16: 斧武士
A17: 100009 | B17: صياد الظل | C17: 狙影猎手
A18: 100010 | B18: نشّاب | C18: 风弩手
A19: 100011 | B19: مُعالج | C19: 愈灵师
A20: 100012 | B20: الروح الشيطانية | C20: 魔灵士
A21: 100013 | B21: مبارز عظيم | C21: 大剑士
... A14322: 301876 | B14322: القواعد الهجومية | C14322: 进攻规则
A14323: 301878
A14324: 301879 | B14324: قواعد التمشيط | C14324: 扫荡规则
A14325: 301881 | B14325: القواعد الدفاعية | C14325: 防守规则
A14326: 301883
A14327: 301884 | B14327: قواعد الإحياء | C14327: 复活规则
A14328: 301886 | B14328: قواعد التراجع | C14328: 撤退规则
A14329: 301888 | B14329: قواعد القتال | C14329: 战斗规则
A14330: 301890 | B14330: قواعد التعادل | C14330: 平局规则
A14331: 301892 | B14331: إضعاف ضرر PVP | C14331: PVP伤害衰减
A14332: 301894 | B14332: قواعد تسوية الموسم | C14332: 赛季结算规则
A14333: 301896 | B14333: قواعد مآثر الحرب PVE | C14333: PVE战功规则
A14334: 301898 | B14334: قوانين مآثر الحرب PVP | C14334: PVP战功规则
A14335: 301900 | B14335: قواعد مآثر الحرب للخادم | C14335: 服务器战功规则
A14336: 301902 | B14336: الحامية | C14336: 驻守
A14337: 301903 | B14337: التحقيق | C14337: 侦查
A14338: 301904 | B14338: مشاركة | C14338: 分享
... A14603: 204837 | B14603: يتعذر بدء الاستيلاء، فترة الهُدنة من الساعة 0 إلى 8 | C14603: 0点-8点为休战期，无法发起抢占
A14604: 700000002 | C14604: 悲伤蛙称号，不需要文字
...

Sheet 注意事项
C2: 阿拉伯语从右往左阅读 程序自己拼的文本会出现问题
B5: 需要修改的内容
C6: 标黄或文本改红
B8: 1 | C8: 包装修改：
C9: 冰龙巢穴——熔焰遗迹
C10: 红包——礼盒
C11: 冰龙——火龙
B14: 2 | C14: 麻烦检查一下变量的位置 比如103528，~的位置错了
F15: 103528 | G15: يا له من محظوظ! لقد أحرز ~s 18 نقطة! | H15: 手气爆棚！##1投出了18点！
F16: 200408 | G16: وقت الفعالية: %s-%s | H16: 活动时间：##1-##2
F17: 200411 | G17: حجم العشيرة (%s/%s) | H17: 家族人数(##1/##2)
B20: 3 | D20: 变量改成
C21: n\ | D21: \n | E21: \n一定要挨在一起，不然无法导进游戏；目前的语言表是研发手动改的，可能有错误，翻译老师注意下
C22: s% | D22: 改成:点进格子是##1
C23: s~ | D23: 改成:点进格子是##1
C24: 1## | D24: 改成:点进格子是##1

Sheet 阿拉伯中文检查表
A1: 0
A2: 语言总表
A3: 索引ID | B3: 中文，用于导出（不要在原表简转繁）
A4: 1*1
A5: id
A6: int
A7: id
A8: int | B8: 英语 | D8: 中文不一样 | E8: 是否需要重新翻译
A9: 100001 | B9: T后台纯文本邮件模板 | C9: =VLOOKUP(A9,out_language_ar!A:C,3,0) | D9: =IF(C9=B9,"")
A10: 100002 | B10: T后台文本+奖励邮件模板 | C10: =VLOOKUP(A10,out_language_ar!A:C,3,0) | D10: =IF(C10=B10,"")
A11: 100003 | B11: 菇勇者 | C11: =VLOOKUP(A11,out_language_ar!A:C,3,0) | D11: =IF(C11=B11,"")
A12: 100004 | B12: 战士 | C12: =VLOOKUP(A12,out_language_ar!A:C,3,0) | D12: =IF(C12=B12,"")
A13: 100005 | B13: 弓箭手 | C13: =VLOOKUP(A13,out_language_ar!A:C,3,0) | D13: =IF(C13=B13,"")
A14: 100006 | B14: 法师 | C14: =VLOOKUP(A14,out_language_ar!A:C,3,0) | D14: =IF(C14=B14,"")
A15: 100007 | B15: 剑客 | C15: =VLOOKUP(A15,out_language_ar!A:C,3,0) | D15: =IF(C15=B15,"")
A16: 100008 | B16: 斧武士 | C16: =VLOOKUP(A16,out_language_ar!A:C,3,0) | D16: =IF(C16=B16,"")
A17: 100009 | B17: 狙影猎手 | C17: =VLOOKUP(A17,out_language_ar!A:C,3,0) | D17: =IF(C17=B17,"")
A18: 100010 | B18: 风弩手 | C18: =VLOOKUP(A18,out_language_ar!A:C,3,0) | D18: =IF(C18=B18,"")
A19: 100011 | B19: 愈灵师 | C19: =VLOOKUP(A19,out_language_ar!A:C,3,0) | D19: =IF(C19=B19,"")
A20: 100012 | B20: 魔灵士 | C20: =VLOOKUP(A20,out_language_ar!A:C,3,0) | D20: =IF(C20=B20,"")
... A1287: 101289 | B1287: 七彩葫芦 | C1287: =VLOOKUP(A1287,out_language_ar!A:C,3,0) | D1287: =IF(C1287=B1287,"")
A1288: 101290 | B1288: ~s加入家族 | C1288: =VLOOKUP(A1288,out_language_ar!A:C,3,0) | D1288: =IF(C1288=B1288,"") | E1288: 0
A1289: 101291 | B1289: ~s职务调整为~s | C1289: =VLOOKUP(A1289,out_language_ar!A:C,3,0) | D1289: =IF(C1289=B1289,"") | E1289: 0
A1290: 101292 | B1290: 族长 | C1290: =VLOOKUP(A1290,out_language_ar!A:C,3,0) | D1290: =IF(C1290=B1290,"")
A1291: 101293 | B1291: 长老 | C1291: =VLOOKUP(A1291,out_language_ar!A:C,3,0) | D1291: =IF(C1291=B1291,"")
A1292: 101294 | B1292: 家族宝贝 | C1292: =VLOOKUP(A1292,out_language_ar!A:C,3,0) | D1292: =IF(C1292=B1292,"")
A1293: 101295 | B1293: 精英 | C1293: =VLOOKUP(A1293,out_language_ar!A:C,3,0) | D1293: =IF(C1293=B1293,"")
A1294: 101296 | B1294: 成员 | C1294: =VLOOKUP(A1294,out_language_ar!A:C,3,0) | D1294: =IF(C1294=B1294,"")
A1295: 101297 | B1295: 剑首 | C1295: =VLOOKUP(A1295,out_language_ar!A:C,3,0) | D1295: =IF(C1295=B1295,"")
A1296: 101298 | B1296: 战狂 | C1296: =VLOOKUP(A1296,out_language_ar!A:C,3,0) | D1296: =IF(C1296=B1296,"")
A1297: 101299 | B1297: 影狩 | C1297: =VLOOKUP(A1297,out_language_ar!A:C,3,0) | D1297: =IF(C1297=B1297,"")
A1298: 101300 | B1298: 箭神 | C1298: =VLOOKUP(A1298,out_language_ar!A:C,3,0) | D1298: =IF(C1298=B1298,"")
A1299: 101301 | B1299: 圣导 | C1299: =VLOOKUP(A1299,out_language_ar!A:C,3,0) | D1299: =IF(C1299=B1299,"")
A1300: 101302 | B1300: 主教 | C1300: =VLOOKUP(A1300,out_language_ar!A:C,3,0) | D1300: =IF(C1300=B1300,"")
A1301: 101303 | B1301: 棒球 | C1301: =VLOOKUP(A1301,out_language_ar!A:C,3,0) | D1301: =IF(C1301=B1301,"")
... A1684: 101686 | B1684: 萌猫小耳 | C1684: =VLOOKUP(A1684,out_language_ar!A:C,3,0) | D1684: =IF(C1684=B1684,"")
A1685: 101687 | B1685: 噗叽西红柿头饰 | C1685: =VLOOKUP(A1685,out_language_ar!A:C,3,0) | D1685: =IF(C1685=B1685,"") | E1685: 0
A1686: 101688 | B1686: 萝卜头饰 | C1686: =VLOOKUP(A1686,out_language_ar!A:C,3,0) | D1686: =IF(C1686=B1686,"")
A1687: 101689 | B1687: 团圆绿粽头饰 | C1687: =VLOOKUP(A1687,out_language_ar!A:C,3,0) | D1687: =IF(C1687=B1687,"")
A1688: 101690 | B1688: 粉红章鱼头饰 | C1688: =VLOOKUP(A1688,out_language_ar!A:C,3,0) | D1688: =IF(C1688=B1688,"")
...

Sheet 翻译进度确认表
A1: 0
A2: 语言总表
A3: 索引ID | B3: 内容 | C3: 中文，用于导出（不要在原表简转繁）
A4: 1*1 | B4: stack_error,n_list
A5: id | B5: text
A6: int | B6: string
A7: id | B7: text
A8: int | B8: ori_string
A9: 100001 | B9: T Backend Text-Only Mail Template | C9: T后台纯文本邮件模板 | D9: =IFERROR(VLOOKUP(A9,out_language_ar!A:C,1,0),AAA未翻译)
A10: 100002 | B10: T Backend Text&Rewards Mail Template | C10: T后台文本+奖励邮件模板 | D10: =IFERROR(VLOOKUP(A10,out_language_ar!A:C,1,0),AAA未翻译)
A11: 100003 | B11: Shroomie | C11: 菇勇者 | D11: =IFERROR(VLOOKUP(A11,out_language_ar!A:C,1,0),AAA未翻译)
A12: 100004 | B12: Warrior | C12: 战士 | D12: =IFERROR(VLOOKUP(A12,out_language_ar!A:C,1,0),AAA未翻译)
A13: 100005 | B13: Archer | C13: 弓箭手 | D13: =IFERROR(VLOOKUP(A13,out_language_ar!A:C,1,0),AAA未翻译)
A14: 100006 | B14: Mage | C14: 法师 | D14: =IFERROR(VLOOKUP(A14,out_language_ar!A:C,1,0),AAA未翻译)
A15: 100007 | B15: Swordsman | C15: 剑客 | D15: =IFERROR(VLOOKUP(A15,out_language_ar!A:C,1,0),AAA未翻译)
A16: 100008 | B16: Axe Warrior | C16: 斧武士 | D16: =IFERROR(VLOOKUP(A16,out_language_ar!A:C,1,0),AAA未翻译)
A17: 100009 | B17: Shadow Sniper | C17: 狙影猎手 | D17: =IFERROR(VLOOKUP(A17,out_language_ar!A:C,1,0),AAA未翻译)
A18: 100010 | B18: Wind Crossbower | C18: 风弩手 | D18: =IFERROR(VLOOKUP(A18,out_language_ar!A:C,1,0),AAA未翻译)
A19: 100011 | B19: Healer | C19: 愈灵师 | D19: =IFERROR(VLOOKUP(A19,out_language_ar!A:C,1,0),AAA未翻译)
A20: 100012 | B20: Spellcaster | C20: 魔灵士 | D20: =IFERROR(VLOOKUP(A20,out_language_ar!A:C,1,0),AAA未翻译)
... A4982: 200662 | B4982: Exchange | C4982: 兑换 | D4982: =IFERROR(VLOOKUP(A4982,out_language_ar!A:C,1,0),AAA未翻译)
A4983: 200663 | B4983: 1 | C4983: 一 | D4983: =IFERROR(VLOOKUP(A4983,out_language_ar!A:C,1,0),AAA未翻译)
A4984: 200664 | B4984: 2 | C4984: 二 | D4984: =IFERROR(VLOOKUP(A4984,out_language_ar!A:C,1,0),AAA未翻译)
A4985: 200665 | B4985: 3 | C4985: 三 | D4985: =IFERROR(VLOOKUP(A4985,out_language_ar!A:C,1,0),AAA未翻译)
A4986: 200666 | B4986: 4 | C4986: 四 | D4986: =IFERROR(VLOOKUP(A4986,out_language_ar!A:C,1,0),AAA未翻译)
A4987: 200667 | B4987: 5 | C4987: 五 | D4987: =IFERROR(VLOOKUP(A4987,out_language_ar!A:C,1,0),AAA未翻译)
A4988: 200668 | B4988: 6 | C4988: 六 | D4988: =IFERROR(VLOOKUP(A4988,out_language_ar!A:C,1,0),AAA未翻译)
A4989: 200669 | B4989: 7 | C4989: 七 | D4989: =IFERROR(VLOOKUP(A4989,out_language_ar!A:C,1,0),AAA未翻译)
A4990: 200670 | B4990: 8 | C4990: 八 | D4990: =IFERROR(VLOOKUP(A4990,out_language_ar!A:C,1,0),AAA未翻译)
A4991: 200671 | B4991: 9 | C4991: 九 | D4991: =IFERROR(VLOOKUP(A4991,out_language_ar!A:C,1,0),AAA未翻译)
A4992: 200672 | B4992: Handbook | C4992: 图鉴 | D4992: =IFERROR(VLOOKUP(A4992,out_language_ar!A:C,1,0),AAA未翻译)
A4993: 200673 | B4993: Courage Challenges | C4993: 常规勇气挑战 | D4993: =IFERROR(VLOOKUP(A4993,out_language_ar!A:C,1,0),AAA未翻译)
A4994: 200674 | B4994: Exclusive Battle Trial | C4994: 专属战斗试炼 | D4994: =IFERROR(VLOOKUP(A4994,out_language_ar!A:C,1,0),AAA未翻译)
A4995: 200675 | B4995: Farm Experience | C4995: 农庄体验 | D4995: =IFERROR(VLOOKUP(A4995,out_language_ar!A:C,1,0),AAA未翻译)
A4996: 200676 | B4996: Invited Tour | C4996: 特邀行程 | D4996: =IFERROR(VLOOKUP(A4996,out_language_ar!A:C,1,0),AAA未翻译)
A4997: 200677 | B4997: World | C4997: 世界 | D4997: =IFERROR(VLOOKUP(A4997,out_language_ar!A:C,1,0),AAA未翻译)
A4998: 200678 | B4998: Family | C4998: 家族 | D4998: =IFERROR(VLOOKUP(A4998,out_language_ar!A:C,1,0),AAA未翻译)
A4999: 200679 | B4999: Private | C4999: 私聊 | D4999: =IFERROR(VLOOKUP(A4999,out_language_ar!A:C,1,0),AAA未翻译)
A5000: 200680 | B5000: News | C5000: 新闻 | D5000: =IFERROR(VLOOKUP(A5000,out_language_ar!A:C,1,0),AAA未翻译)
A5001: 200681 | B5001: Server Ranking | C5001: 服务器排名 | D5001: =IFERROR(VLOOKUP(A5001,out_language_ar!A:C,1,0),AAA未翻译)
...

Sheet Sheet1
A1: 0
A2: 语言总表
A3: 索引ID | B3: 内容
A4: 1*1 | B4: stack_error,n_list
A5: id | B5: text
A6: int | B6: string
A7: id | B7: text
A8: int | B8: ori_string
A9: 100001 | B9: T后台纯文本邮件模板
A10: 100002 | B10: T后台文本+奖励邮件模板
A11: 100003 | B11: 菇勇者
A12: 100004 | B12: 战士
A13: 100005 | B13: 弓箭手
A14: 100006 | B14: 法师
A15: 100007 | B15: 剑客
A16: 100008 | B16: 斧武士
A17: 100009 | B17: 狙影猎手
A18: 100010 | B18: 风弩手 | E18: ط-سيتم استبدال جميع عملات الرهان بنقاط الرهان في نهاية الفاعلية، ويستطيع اللاعبون استخدام نقاط الرهان الخاصة بهم لتبادل الدعائم في المتجر. ح-يستطيع الاعبين اكتساب أو شراء عملات الرهان في المتجر خلال مراحل الكل ضد الكل والإقصاء، وأفضل لاعب يمكن تقديم اسمه عن طريق الرهان خلال جولة الكل ضد الكل وسيتوقف الرهان عند الساعة 18:30 في يوم انتهاء الجولة، بينما تتوقف الفرق التي يمكنها التقدم خلال مرحلة الكل ضد الكل عن الرهان عند الساعة 19:30 في يوم مرحلة الإقصاء، وسيحصلون على عملات الرهان مع الإحتمالات المقابلة عند فوزهم، وسيتم إعادة نصف قطع التخمين إذا فشل الرهان.\n ز-المرحلة السادسة هي فترة الاحتفال، والتي يتم خلالها تقدير بطل هذه الدورة.\nو-المرحلة الخامسة هي المرحلة الإقصائية، حيث يتم تقسيم اللاعبين في أزواج ويتقاتلون في الساعة 20:00 من نفس اليوم، ويتقدم الفريق الفائز حتى يتم تحديد البطل.\n ه‎-المرحلة الرابعة هي مرحلة الكل ضد الكل، حيث يتم تقسيم أفضل 128 لاعبًا إلى 16 مجموعة. سيتنافس اللاعبون الثمانية في كل مجموعة في أزواج الساعة 19:00 يوم المباراة بإجمالي 7 مباريات، سيدخل أفضل لاعبين ذوي أكبر عدد من المباريات إلى أفضل 32 لاعبًا بإستخدام طريقة أفضل محاولتان من أصل ثلاثة، وسيتم تقسيم ال32 لاعبًا بعدها إلى 4 مجموعات وسيتأهل أفضل فريقين في كل مجموعة إلى المرحلة الإقصائية من ربع النهائي. إذا تماثلت الفرق الفائزة فسيحصل الفريق ذو أكبر عدد من الانتصارات الصافية على مرتبة أعلى، وسيعتمد الترتيب على علاقة الفوز بالخسارة للفريق في حال التساوي، وإذا كانت هناك حلقة مغلقة بين الفوز والخسارة فسيعتمد الترتيب على نقاط الجولة التمهيدية.\nد-المرحلة الثالثة هي فترة الإعداد، حيث يمكن للاعبين تحديد قوة الخصوم المختلفين في مرحلة الكل ضد الكل من خلال استكشاف أفضل 128 لاعبًا.\nج-المرحلة الثانية هي فترة التصنيف، وبها يستطيع اللاعبون تحدي الفرق الأُخرى من الساعة 10:00 إلى الساعة 22:00 يوميًا بعد تشكيل الفريق، ويحصل اللاعبون على 10 فرص تحدي عند تشكيل فريقًا فرديًا و 5 فرص تحدي عند تشكيل فريقًا زوجيًا. ستحصل على نتائج مختلفة بعد التحدي والانتصار على الفرق المختلفة، كما ستحصل على نقاط إضافية كلما قصر الوقت المستغرق لهزيمة الخصم، وسيتم خصم النقاط المقابلة للفرق المهزومة، وسيتأهل أعلى 128 لاعب إلى مرحلة الكل ضد الكل في نهاية فترة التصفيات.\nب-المرحلة الأولى هي فترة التسجيل، حيث يمكن للاعبين إنشاء فرقهم الخاصة أو الإنضمام إلى فرق الآخرين من خلال البحث عن تعريفات الفرق.\nأ-رابطة الفطر للفنون القتالية عبارة عن لعبة قتال جماعية مكونة من لاعبين تمتد عبر الخادم بأكمله في المنطقة، وتنقسم إلى ست مراحل.\n
A19: 100011 | B19: 愈灵师
A20: 100012 | B20: 魔灵士
A21: 100013 | B21: 大剑士
A22: 100014 | B22: 狂斗士
A23: 100015 | B23: 神射手
A24: 100016 | B24: 双弩英雄
A25: 100017 | B25: 时空咏者
A26: 100018 | B26: 风暴祭司
A27: 100019 | B27: 金币
A28: 100020 | B28: 钻石
A29: 100021 | B29: 经验
A30: 100022 | B30: 遗物碎片
... A13293: 700000003 | B13293: 增加##1%暴击,笨尼攻击有##2%概率击飞目标##3秒
A13294: 700000002
A13295: 400080 | B13295: 待寻找
A13296: 400534 | B13296: 当前难度开放满3天且通关时防御值为10解锁扫荡
A13297: 400535 | B13297: 通关当前难度且防御值为10时解锁扫荡
A13298: 400536 | B13298: 悲伤蛙好感：
A13299: 400537 | B13299: 悲伤蛙宇宙
A13300: 400538 | B13300: 躲蛙蛙
A13301: 400539 | B13301: 守卫佛系蛙
A13302: 400540 | B13302: 失眠蛙
...
