Workbook

Sheet out_language_en
A1: 0
A2: 语言总表
A3: 索引ID | B3: 内容 | C3: 中文，用于导出（不要在原表简转繁）
A4: 1*1 | B4: stack_error,n_list
A5: id | B5: text
A6: int | B6: string
A7: id | B7: text
A8: int | B8: ori_string
A9: 100001 | B9: T Backend Text-Only Mail Template | C9: T后台纯文本邮件模板 | D9: =VLOOKUP(A9,Sheet1!A:C,2,0) | E9: D列为简中语言表的文本，若CD列中文有冲突，以D列为准
A10: 100002 | B10: T Backend Text&Rewards Mail Template | C10: T后台文本+奖励邮件模板 | D10: =VLOOKUP(A10,Sheet1!A:C,2,0)
A11: 100003 | B11: Shroomie | C11: 菇勇者 | D11: =VLOOKUP(A11,Sheet1!A:C,2,0)
A12: 100004 | B12: Warrior | C12: 战士 | D12: =VLOOKUP(A12,Sheet1!A:C,2,0)
A13: 100005 | B13: Archer | C13: 弓箭手 | D13: =VLOOKUP(A13,Sheet1!A:C,2,0)
A14: 100006 | B14: Mage | C14: 法师 | D14: =VLOOKUP(A14,Sheet1!A:C,2,0)
A15: 100007 | B15: Swordsman | C15: 剑客 | D15: =VLOOKUP(A15,Sheet1!A:C,2,0)
A16: 100008 | B16: Axe Warrior | C16: 斧武士 | D16: =VLOOKUP(A16,Sheet1!A:C,2,0)
A17: 100009 | B17: Shadow Sniper | C17: 狙影猎手 | D17: =VLOOKUP(A17,Sheet1!A:C,2,0)
A18: 100010 | B18: Wind Crossbower | C18: 风弩手 | D18: =VLOOKUP(A18,Sheet1!A:C,2,0)
A19: 100011 | B19: Healer | C19: 愈灵师 | D19: =VLOOKUP(A19,Sheet1!A:C,2,0)
A20: 100012 | B20: Spellcaster | C20: 魔灵士 | D20: =VLOOKUP(A20,Sheet1!A:C,2,0)
A21: 100013 | B21: Claymore Wielder | C21: 大剑士 | D21: =VLOOKUP(A21,Sheet1!A:C,2,0)
... A4418: 200094 | B4418: Spend %s? | C4418: 是否消耗%s | D4418: =VLOOKUP(A4418,Sheet1!A:C,2,0)
A4419: 700024509 | B4419: Spend ##1*##2? | C4419: 是否消耗##1*##2
A4420: 200095 | B4420: Reforge | C4420: 重铸 | D4420: =VLOOKUP(A4420,Sheet1!A:C,2,0)
A4421: 200096 | B4421: <b><color=#544231>Milestone: Mileage reaches </color><color=#ab630e>%s</color></b> | C4421: <b><color=#544231>里程目标：里程值达到</color><color=#ab630e>%s</color></b> | D4421: =VLOOKUP(A4421,Sheet1!A:C,2,0)
A4422: 200097 | B4422: <b><color=#544231>Milestone: Complete event Dungeon </color><color=#ab630e>%s</color></b> | C4422: <b><color=#544231>里程目标：通关活动副本</color><color=#ab630e>%s</color></b> | D4422: =VLOOKUP(A4422,Sheet1!A:C,2,0)
A4423: 200098 | B4423: Deploy Effect: %s | C4423: 上阵效果：%s | D4423: =VLOOKUP(A4423,Sheet1!A:C,2,0)
A4424: 200099 | B4424: Base HP, ATK, DEF +%s% | C4424: 基础生命&攻击&防御+%s% | D4424: =VLOOKUP(A4424,Sheet1!A:C,2,0)
A4425: 200100 | B4425: No pals available for equipment | C4425: 没有可以装配的同伴 | D4425: =VLOOKUP(A4425,Sheet1!A:C,2,0)
A4426: 200101 | B4426: Unlock | C4426: 解锁 | D4426: =VLOOKUP(A4426,Sheet1!A:C,2,0)
A4427: 200102 | B4427: Event Duration: %s | C4427: 活动时间：%s | D4427: =VLOOKUP(A4427,Sheet1!A:C,2,0)
A4428: 200103 | B4428: Basic Attributes | C4428: 基础属性 | D4428: =VLOOKUP(A4428,Sheet1!A:C,2,0)
A4429: 200104 | B4429: Advanced Attributes | C4429: 高级属性 | D4429: =VLOOKUP(A4429,Sheet1!A:C,2,0)
A4430: 200105 | B4430: Final Attributes | C4430: 最终属性 | D4430: =VLOOKUP(A4430,Sheet1!A:C,2,0)
A4431: 200106 | B4431: Insufficient level | C4431: 等级不足 | D4431: =VLOOKUP(A4431,Sheet1!A:C,2,0)
... A4981: 200662 | B4981: Exchange | C4981: 兑换 | D4981: =VLOOKUP(A4981,Sheet1!A:C,2,0)
A4982: 200663 | B4982: 1 | C4982: 一 | D4982: =VLOOKUP(A4982,Sheet1!A:C,2,0)
A4983: 200664 | B4983: 2 | C4983: 二 | D4983: =VLOOKUP(A4983,Sheet1!A:C,2,0)
A4984: 200665 | B4984: 3 | C4984: 三 | D4984: =VLOOKUP(A4984,Sheet1!A:C,2,0)
A4985: 200666 | B4985: 4 | C4985: 四 | D4985: =VLOOKUP(A4985,Sheet1!A:C,2,0)
...

Sheet Sheet1
A1: 0
A2: 语言总表
A3: 索引ID | B3: 内容
A4: 1*1 | B4: stack_error,n_list | C4: 外语查找用这列
A5: id | B5: text
A6: int | B6: string
A7: id | B7: text
A8: int | B8: ori_string
A9: 100001 | B9: T后台纯文本邮件模板 | C9: T后台纯文本邮件模板
A10: 100002 | B10: T后台文本+奖励邮件模板 | C10: T后台文本+奖励邮件模板
A11: 100003 | B11: 菇勇者 | C11: 菇勇者
A12: 100004 | B12: 战士 | C12: 战士
A13: 100005 | B13: 弓箭手 | C13: 弓箭手
A14: 100006 | B14: 法师 | C14: 法师
A15: 100007 | B15: 剑客 | C15: 剑客
A16: 100008 | B16: 斧武士 | C16: 斧武士
A17: 100009 | B17: 狙影猎手 | C17: 狙影猎手
A18: 100010 | B18: 风弩手 | C18: 风弩手
A19: 100011 | B19: 愈灵师 | C19: 愈灵师
A20: 100012 | B20: 魔灵士 | C20: 魔灵士
... A13293: 700000003 | B13293: 增加##1%暴击,笨尼攻击有##2%概率击飞目标##3秒 | C13293: 增加##1%暴击,笨尼攻击有##2%概率击飞目标##3秒
A13294: 700000002 | C13294: 悲伤蛙称号，不需要文字
A13295: 400080 | B13295: 待寻找 | C13295: 待寻找
A13296: 400534 | B13296: 当前难度开放满3天且通关时防御值为10解锁扫荡 | C13296: 当前难度开放满3天且通关时防御值为10解锁扫荡
A13297: 400535 | B13297: 通关当前难度且防御值为10时解锁扫荡 | C13297: 通关当前难度且防御值为10时解锁扫荡
A13298: 400536 | B13298: 悲伤蛙好感： | C13298: 悲伤蛙好感：
A13299: 400537 | B13299: 悲伤蛙宇宙 | C13299: 悲伤蛙宇宙
A13300: 400538 | B13300: 躲蛙蛙 | C13300: 躲蛙蛙
A13301: 400539 | B13301: 守卫佛系蛙 | C13301: 守卫佛系蛙
A13302: 400540 | B13302: 失眠蛙 | C13302: 失眠蛙
A13303: 400541 | B13303: 星球之旅 | C13303: 星球之旅
A13304: 400542 | B13304: 高光时刻 | C13304: 高光时刻
A13305: 400543 | B13305: 打爆不开心 | C13305: 打爆不开心
A13306: 400544 | B13306: 太空历险蛙 | C13306: 太空历险蛙
... A14889: 301877 | B14889: 1、每次进攻，都需消耗1点行动力\n2、发起进攻操作，玩家到达目标地块后进入进攻队列，按队列顺序先后挑战守军\n2、若进攻成功，进攻方击败了所有守军，则该地块的所有权变更\n3、若进攻失败，玩家阵亡，则玩家会在10分钟后在设置的复活点复活（大本营、据点Lv3均可作为复活点） | C14889: 1、每次进攻，都需消耗1点行动力\n2、发起进攻操作，玩家到达目标地块后进入进攻队列，按队列顺序先后挑战守军\n2、若进攻成功，进攻方击败了所有守军，则该地块的所有权变更\n3、若进攻失败，玩家阵亡，则玩家会在10分钟后在设置的复活点复活（大本营、据点Lv3均可作为复活点）
A14890: 301878
A14891: 301879 | B14891: 扫荡规则 | C14891: 扫荡规则
A14892: 301880 | B14892: 1、对已占领的资源地块，可进行扫荡操作\n2、每次扫荡将消耗1点行动力，扫荡时击败守军，可获得【PVE战功】及【铁锭】（同进攻操作） | C14892: 1、对已占领的资源地块，可进行扫荡操作\n2、每次扫荡将消耗1点行动力，扫荡时击败守军，可获得【PVE战功】及【铁锭】（同进攻操作）
A14893: 301881 | B14893: 防守规则 | C14893: 防守规则
A14894: 301882 | B14894: 1、驻守后将玩家算进该地块的防守队列\n2、驻守状态，每1分钟可恢复10%最大生命值的血量\n3、若防守成功，防守者击败了所有进攻者，则该地块的所有权维持原状\n4、若防守失败，所有防守者被击败，则地块归属权变更 | C14894: 1、驻守后将玩家算进该地块的防守队列\n2、驻守状态，每1分钟可恢复10%最大生命值的血量\n3、若防守成功，防守者击败了所有进攻者，则该地块的所有权维持原状\n4、若防守失败，所有防守者被击败，则地块归属权变更
...

Sheet Sheet2
C14: Marry me please!
C15: 愿未来的岁月充满爱和快乐。
C16: 天作之合，缘聚两心！
C17: 彼此相爱，互敬互爱。
C18: 命运美好，奇迹即将降临！
C19: 你们就是童话中的王子和公主，愿你们幸福永远！
C20: 爱会找到出路~
C21: 一句话，一生情，一世爱，一杯酒。
C22: 祝愿你们的梦想成真，世界充满幸福和爱。
C23: 我们从未见过如此般配的两个人。
C24: 爱是最伟大的。
C25: 今天是你们新篇章的开始。向你们干杯！
... C33: 凡事都要心存爱心。
