Workbook

Sheet out_language_it
A1: 0
A2: 语言总表
A3: 索引ID | B3: 内容
A4: 1*1 | B4: stack_error,n_list
A5: id | B5: text
A6: int | B6: string
A7: id | B7: text
A8: int | B8: ori_string
A9: 100001 | B9: Modello di posta testuale per il backend T | C9: T后台纯文本邮件模板 | D9: =VLOOKUP(A9,Sheet1!A:B,2,0) | E9: D列为简中语言表的文本，若CD列中文有冲突，以D列为准
A10: 100002 | B10: Modello di posta delle ricompense + testo di backend T | C10: T后台文本+奖励邮件模板 | D10: =VLOOKUP(A10,Sheet1!A:B,2,0)
A11: 100003 | B11: Funghetto | C11: 菇勇者 | D11: =VLOOKUP(A11,Sheet1!A:B,2,0)
A12: 100004 | B12: Guerriero | C12: 战士 | D12: =VLOOKUP(A12,Sheet1!A:B,2,0)
A13: 100005 | B13: Arciere | C13: 弓箭手 | D13: =VLOOKUP(A13,Sheet1!A:B,2,0)
A14: 100006 | B14: Mago | C14: 法师 | D14: =VLOOKUP(A14,Sheet1!A:B,2,0)
A15: 100007 | B15: Spadaccino | C15: 剑客 | D15: =VLOOKUP(A15,Sheet1!A:B,2,0)
A16: 100008 | B16: Barbaro | C16: 斧武士 | D16: =VLOOKUP(A16,Sheet1!A:B,2,0)
A17: 100009 | B17: Cacciatore d'agguato | C17: 狙影猎手 | D17: =VLOOKUP(A17,Sheet1!A:B,2,0)
A18: 100010 | B18: Balestriere del Vento | C18: 风弩手 | D18: =VLOOKUP(A18,Sheet1!A:B,2,0)
A19: 100011 | B19: Guaritore | C19: 愈灵师 | D19: =VLOOKUP(A19,Sheet1!A:B,2,0)
A20: 100012 | B20: Incantatore | C20: 魔灵士 | D20: =VLOOKUP(A20,Sheet1!A:B,2,0)
A21: 100013 | B21: Maestro della Spada | C21: 大剑士 | D21: =VLOOKUP(A21,Sheet1!A:B,2,0)
... A4418: 200094 | B4418: Desideri utilizzare %s | C4418: 是否消耗%s | D4418: =VLOOKUP(A4418,Sheet1!A:B,2,0)
A4419: 700024509 | B4419: Desideri utilizzare ##1*##2 | C4419: 是否消耗##1*##2
A4420: 200095 | B4420: Fondi di nuovo | C4420: 重铸 | D4420: =VLOOKUP(A4420,Sheet1!A:B,2,0)
A4421: 200096 | B4421: <b><color=#544231>Obiettivo della via: ottieni i Punti miliari</color><color=#ab630e>%s</color></b> | C4421: <b><color=#544231>里程目标：里程值达到</color><color=#ab630e>%s</color></b> | D4421: =VLOOKUP(A4421,Sheet1!A:B,2,0)
A4422: 200097 | B4422: <b><color=#544231>Obiettivo della via: completa il dungeon dell'evento</color><color=#ab630e>%s</color></b> | C4422: <b><color=#544231>里程目标：通关活动副本</color><color=#ab630e>%s</color></b> | D4422: =VLOOKUP(A4422,Sheet1!A:B,2,0)
A4423: 200098 | B4423: Effetto sul Campo: %s | C4423: 上阵效果：%s | D4423: =VLOOKUP(A4423,Sheet1!A:B,2,0)
A4424: 200099 | B4424: Punti Vita di base & Attacco & Difesa +%s% | C4424: 基础生命&攻击&防御+%s% | D4424: =VLOOKUP(A4424,Sheet1!A:B,2,0)
A4425: 200100 | B4425: Non ci sono alleati da radunare | C4425: 没有可以装配的同伴 | D4425: =VLOOKUP(A4425,Sheet1!A:B,2,0)
A4426: 200101 | B4426: Sblocca | C4426: 解锁 | D4426: =VLOOKUP(A4426,Sheet1!A:B,2,0)
A4427: 200102 | B4427: Durata dell'Evento: %s | C4427: 活动时间：%s | D4427: =VLOOKUP(A4427,Sheet1!A:B,2,0)
A4428: 200103 | B4428: Caratteristiche di base | C4428: 基础属性 | D4428: =VLOOKUP(A4428,Sheet1!A:B,2,0)
A4429: 200104 | B4429: Caratteristiche avanzate | C4429: 高级属性 | D4429: =VLOOKUP(A4429,Sheet1!A:B,2,0)
A4430: 200105 | B4430: Caratteristiche ultime | C4430: 最终属性 | D4430: =VLOOKUP(A4430,Sheet1!A:B,2,0)
A4431: 200106 | B4431: Livello non sufficiente | C4431: 等级不足 | D4431: =VLOOKUP(A4431,Sheet1!A:B,2,0)
... A5529: 201236 | B5529: Felice Halloween! Queste sono le tue caramelle | C5529: 万圣节快乐!这是给你的糖果 | D5529: =VLOOKUP(A5529,Sheet1!A:B,2,0)
A5530: 201237 | B5530: Vuoi guardare una pubblicità per aumentare tutti le caratteristiche del 50%? | C5530: 是否观看广告，全属性提升50%？ | D5530: =VLOOKUP(A5530,Sheet1!A:B,2,0) | E5530: 4. Accumulate Remodel Points for mount enhancements; use Remodeling Guides for leveling.\n5. Longer parking results in extra adventure rewards with diverse mounts offering various bonuses.\n6. No additional earnings after parking for over 8 hours; collect rewards promptly.
A5531: 201239 | B5531: Operazione troppo frequente, riprovare più tardi | C5531: 操作过于频繁，请稍后再试 | D5531: =VLOOKUP(A5531,Sheet1!A:B,2,0) | E5531: 7. After parking for a full 12 hours daily, mounts earn Parking Coins at half the rate and no longer receive remodel points and adventure rewards.\n8. Spot owners receive 5% of total Parking Coin earnings without affecting the mount's owner.\n9. Each mount can be plundered only once. Successful plundering forces the mount to stop parking, and all participating players share a portion of the mount's Parking Coin earnings for that session.
A5532: 201240 | B5532: Fiches Tattiche | C5532: 策略筹码 | D5532: =VLOOKUP(A5532,Sheet1!A:B,2,0)
A5533: 201241 | B5533: Punti Tattici | C5533: 策略值 | D5533: =VLOOKUP(A5533,Sheet1!A:B,2,0)
...

Sheet Sheet1
A1: 0
A2: 语言总表
A3: 索引ID | B3: 内容
A4: 1*1 | B4: stack_error,n_list
A5: id | B5: text
A6: int | B6: string
A7: id | B7: text
A8: int | B8: ori_string
A9: 100001 | B9: T后台纯文本邮件模板
A10: 100002 | B10: T后台文本+奖励邮件模板
A11: 100003 | B11: 菇勇者
A12: 100004 | B12: 战士
A13: 100005 | B13: 弓箭手
A14: 100006 | B14: 法师
A15: 100007 | B15: 剑客
A16: 100008 | B16: 斧武士
A17: 100009 | B17: 狙影猎手
A18: 100010 | B18: 风弩手
A19: 100011 | B19: 愈灵师
A20: 100012 | B20: 魔灵士
... A13293: 700000003 | B13293: 增加##1%暴击,笨尼攻击有##2%概率击飞目标##3秒
A13294: 700000002
A13295: 400080 | B13295: 待寻找
A13296: 400534 | B13296: 当前难度开放满3天且通关时防御值为10解锁扫荡
A13297: 400535 | B13297: 通关当前难度且防御值为10时解锁扫荡
A13298: 400536 | B13298: 悲伤蛙好感：
A13299: 400537 | B13299: 悲伤蛙宇宙
A13300: 400538 | B13300: 躲蛙蛙
A13301: 400539 | B13301: 守卫佛系蛙
A13302: 400540 | B13302: 失眠蛙
A13303: 400541 | B13303: 星球之旅
A13304: 400542 | B13304: 高光时刻
A13305: 400543 | B13305: 打爆不开心
A13306: 400544 | B13306: 太空历险蛙
... A14889: 301877 | B14889: 1、每次进攻，都需消耗1点行动力\n2、发起进攻操作，玩家到达目标地块后进入进攻队列，按队列顺序先后挑战守军\n2、若进攻成功，进攻方击败了所有守军，则该地块的所有权变更\n3、若进攻失败，玩家阵亡，则玩家会在10分钟后在设置的复活点复活（大本营、据点Lv3均可作为复活点）
A14890: 301878
A14891: 301879 | B14891: 扫荡规则
A14892: 301880 | B14892: 1、对已占领的资源地块，可进行扫荡操作\n2、每次扫荡将消耗1点行动力，扫荡时击败守军，可获得【PVE战功】及【铁锭】（同进攻操作）
A14893: 301881 | B14893: 防守规则
A14894: 301882 | B14894: 1、驻守后将玩家算进该地块的防守队列\n2、驻守状态，每1分钟可恢复10%最大生命值的血量\n3、若防守成功，防守者击败了所有进攻者，则该地块的所有权维持原状\n4、若防守失败，所有防守者被击败，则地块归属权变更
...

Sheet Sheet2
C14: Marry me please!
C15: 愿未来的岁月充满爱和快乐。
C16: 天作之合，缘聚两心！
C17: 彼此相爱，互敬互爱。
C18: 命运美好，奇迹即将降临！
C19: 你们就是童话中的王子和公主，愿你们幸福永远！
C20: 爱会找到出路~
C21: 一句话，一生情，一世爱，一杯酒。
C22: 祝愿你们的梦想成真，世界充满幸福和爱。
C23: 我们从未见过如此般配的两个人。
C24: 爱是最伟大的。
C25: 今天是你们新篇章的开始。向你们干杯！
... C33: 凡事都要心存爱心。
